Workbook
Name V_Email_PBPCommon: Admin!$C$5
Name V_Email_PBPCostingManager: Admin!$C$6

Sheet Admin
B4: Email Name | C4: Email
B5: PBP Common Mail Box | C5: examplePBPCommon.email@example.com
B6: PBP Costing Manager | C6: internalpersonPBP@internal.com

Sheet Prices Database
A1: SAP Plant | B1: Customer ref. SAP | C1: Effective | D1: Mailing date | E1: Customer Short Name | F1: Price List Version | G1: Comments about Changes | H1: Price Type (Discount, Net Price) | I1: If Type Discount - Discount % | J1: Price List ID | K1: Product type | L1: RIP code | M1: Product | N1: Net price (Currency / Unit) | O1: Currency | P1: Unit
A2: X22 | B2: XXXXX1 | C2: 36527 | D2: 36526 | E2: =_xlfn.XLOOKUP('Prices Database'!B2,'Customers Masterdata'!F:F,'Customers Masterdata'!G:G) -> Cust A | F2: V1 | G2: New Product | H2: Discount | I2: 0.1 | J2: =B2&C2&D2&F2 -> XXXXX13652736526V1 | K2: Additives | L2: DO1 | M2: PRODUCT 1 | N2: 1301.4 | O2: USD | P2: 100 KG
A3: X22 | B3: XXXXX1 | C3: 36527 | D3: 36526 | E3: =_xlfn.XLOOKUP('Prices Database'!B3,'Customers Masterdata'!F:F,'Customers Masterdata'!G:G) -> Cust A | F3: V1 | G3: New Product | H3: Discount | I3: 0.1 | J3: =B3&C3&D3&F3 -> XXXXX13652736526V1 | K3: Additives | L3: DO2 | M3: PRODUCT 2 | N3: 72.9 | O3: USD | P3: 100 KG
B4: XXXXX1 | C4: 36527 | D4: 36526 | E4: =_xlfn.XLOOKUP('Prices Database'!B4,'Customers Masterdata'!F:F,'Customers Masterdata'!G:G) -> Cust A | F4: V1 | G4: New Product | H4: Discount | I4: 0.1 | J4: =B4&C4&D4&F4 -> XXXXX13652736526V1 | K4: Additives | L4: DO3 | M4: PRODUCT 3 | N4: 414.9 | O4: USD | P4: 100 KG
B5: XXXXX1 | C5: 36527 | D5: 36526 | E5: =_xlfn.XLOOKUP('Prices Database'!B5,'Customers Masterdata'!F:F,'Customers Masterdata'!G:G) -> Cust A | F5: V1 | G5: New Product | H5: Discount | I5: 0.1 | J5: =B5&C5&D5&F5 -> XXXXX13652736526V1 | K5: Additives | L5: DO4 | M5: PRODUCT 4 | N5: 306.9 | O5: USD | P5: 100 KG
B6: XXXXX1 | C6: 36527 | D6: 36526 | E6: =_xlfn.XLOOKUP('Prices Database'!B6,'Customers Masterdata'!F:F,'Customers Masterdata'!G:G) -> Cust A | F6: V1 | G6: New Product | H6: Discount | I6: 0.1 | J6: =B6&C6&D6&F6 -> XXXXX13652736526V1 | K6: Additives | L6: DO5 | M6: PRODUCT 5 | N6: 1512.9 | O6: USD | P6: 100 KG
B7: XXXXX1 | C7: 36527 | D7: 36526 | E7: =_xlfn.XLOOKUP('Prices Database'!B7,'Customers Masterdata'!F:F,'Customers Masterdata'!G:G) -> Cust A | F7: V1 | G7: New Product | H7: Discount | I7: 0.1 | J7: =B7&C7&D7&F7 -> XXXXX13652736526V1 | K7: Additives | L7: DO6 | M7: PRODUCT 6 | N7: 846 | O7: USD | P7: 100 KG
B8: XXXXX1 | C8: 36527 | D8: 36526 | E8: =_xlfn.XLOOKUP('Prices Database'!B8,'Customers Masterdata'!F:F,'Customers Masterdata'!G:G) -> Cust A | F8: V1 | G8: New Product | H8: Discount | I8: 0.1 | J8: =B8&C8&D8&F8 -> XXXXX13652736526V1 | K8: Additives | L8: DO7 | M8: PRODUCT 7 | N8: 897.3 | O8: USD | P8: 100 KG
B9: XXXXX1 | C9: 36527 | D9: 36526 | E9: =_xlfn.XLOOKUP('Prices Database'!B9,'Customers Masterdata'!F:F,'Customers Masterdata'!G:G) -> Cust A | F9: V1 | G9: New Product | H9: Discount | I9: 0.1 | J9: =B9&C9&D9&F9 -> XXXXX13652736526V1 | K9: Additives | L9: DO8 | M9: PRODUCT 8 | N9: 260.1 | O9: USD | P9: 100 KG
B10: XXXXX1 | C10: 36527 | D10: 36526 | E10: =_xlfn.XLOOKUP('Prices Database'!B10,'Customers Masterdata'!F:F,'Customers Masterdata'!G:G) -> Cust A | F10: V1 | G10: New Product | H10: Discount | I10: 0.1 | J10: =B10&C10&D10&F10 -> XXXXX13652736526V1 | K10: Additives | L10: DO9 | M10: PRODUCT 9 | N10: 612.9 | O10: USD | P10: 100 KG
B11: XXXXX1 | C11: 36527 | D11: 36526 | E11: =_xlfn.XLOOKUP('Prices Database'!B11,'Customers Masterdata'!F:F,'Customers Masterdata'!G:G) -> Cust A | F11: V1 | G11: New Product | H11: Discount | I11: 0.1 | J11: =B11&C11&D11&F11 -> XXXXX13652736526V1 | K11: Additives | L11: DO10 | M11: PRODUCT 10 | N11: 927.9 | O11: USD | P11: 100 KG
B12: XXXXX1 | C12: 36527 | D12: 36526 | E12: =_xlfn.XLOOKUP('Prices Database'!B12,'Customers Masterdata'!F:F,'Customers Masterdata'!G:G) -> Cust A | F12: V1 | G12: New Product | H12: Discount | I12: 0.1 | J12: =B12&C12&D12&F12 -> XXXXX13652736526V1 | K12: Additives | L12: DO11 | M12: PRODUCT 11 | N12: 733.5 | O12: USD | P12: 100 KG
B13: XXXXX1 | C13: 36527 | D13: 36526 | E13: =_xlfn.XLOOKUP('Prices Database'!B13,'Customers Masterdata'!F:F,'Customers Masterdata'!G:G) -> Cust A | F13: V1 | G13: New Product | H13: Discount | I13: 0.1 | J13: =B13&C13&D13&F13 -> XXXXX13652736526V1 | K13: Additives | L13: DO12 | M13: PRODUCT 12 | N13: 228.6 | O13: USD | P13: 100 KG
B14: XXXXX1 | C14: 36527 | D14: 36526 | E14: =_xlfn.XLOOKUP('Prices Database'!B14,'Customers Masterdata'!F:F,'Customers Masterdata'!G:G) -> Cust A | F14: V1 | G14: New Product | H14: Discount | I14: 0.1 | J14: =B14&C14&D14&F14 -> XXXXX13652736526V1 | K14: Additives | L14: DO13 | M14: PRODUCT 13 | N14: 1214.1 | O14: USD | P14: 100 KG
B15: XXXXX1 | C15: 36527 | D15: 36526 | E15: =_xlfn.XLOOKUP('Prices Database'!B15,'Customers Masterdata'!F:F,'Customers Masterdata'!G:G) -> Cust A | F15: V1 | G15: New Product | H15: Discount | I15: 0.1 | J15: =B15&C15&D15&F15 -> XXXXX13652736526V1 | K15: EAL | L15: QS1 | M15: PRODUCT 14 | N15: 1053.9 | O15: USD | P15: 100 L
... B43: XXXXX1 | C43: 36527 | D43: 36526 | E43: =_xlfn.XLOOKUP('Prices Database'!B43,'Customers Masterdata'!F:F,'Customers Masterdata'!G:G) -> Cust A | F43: V1 | G43: New Product | H43: Discount | I43: 0 | J43: =B43&C43&D43&F43 -> XXXXX13652736526V1 | K43: Synthetic auxiliary | L43: QS29 | M43: PRODUCT 42 | N43: 1298 | O43: USD | P43: 100 L
A44: X22 | B44: XXXXX1 | C44: 45444 | D44: 45454 | E44: =_xlfn.XLOOKUP('Prices Database'!B44,'Customers Masterdata'!F:F,'Customers Masterdata'!G:G) -> Cust A | F44: V2 | G44: No Changes | H44: Discount | I44: 0.1 | J44: =B44&C44&D44&F44 -> XXXXX14544445454V2 | K44: Additives | L44: DO1 | M44: PRODUCT 1 | N44: 1301.4 | O44: USD | P44: 100 KG
A45: X22 | B45: XXXXX1 | C45: 45444 | D45: 45454 | E45: =_xlfn.XLOOKUP('Prices Database'!B45,'Customers Masterdata'!F:F,'Customers Masterdata'!G:G) -> Cust A | F45: V2 | G45: No Changes | H45: Discount | I45: 0.1 | J45: =B45&C45&D45&F45 -> XXXXX14544445454V2 | K45: Additives | L45: DO2 | M45: PRODUCT 2 | N45: 72.9 | O45: USD | P45: 100 KG
B46: XXXXX1 | C46: 45444 | D46: 45454 | E46: =_xlfn.XLOOKUP('Prices Database'!B46,'Customers Masterdata'!F:F,'Customers Masterdata'!G:G) -> Cust A | F46: V2 | G46: No Changes | H46: Discount | I46: 0.1 | J46: =B46&C46&D46&F46 -> XXXXX14544445454V2 | K46: Additives | L46: DO3 | M46: PRODUCT 3 | N46: 414.9 | O46: USD | P46: 100 KG
B47: XXXXX1 | C47: 45444 | D47: 45454 | E47: =_xlfn.XLOOKUP('Prices Database'!B47,'Customers Masterdata'!F:F,'Customers Masterdata'!G:G) -> Cust A | F47: V2 | G47: No Changes | H47: Discount | I47: 0.1 | J47: =B47&C47&D47&F47 -> XXXXX14544445454V2 | K47: Additives | L47: DO4 | M47: PRODUCT 4 | N47: 306.9 | O47: USD | P47: 100 KG
B48: XXXXX1 | C48: 45444 | D48: 45454 | E48: =_xlfn.XLOOKUP('Prices Database'!B48,'Customers Masterdata'!F:F,'Customers Masterdata'!G:G) -> Cust A | F48: V2 | G48: No Changes | H48: Discount | I48: 0.1 | J48: =B48&C48&D48&F48 -> XXXXX14544445454V2 | K48: Additives | L48: DO5 | M48: PRODUCT 5 | N48: 1512.9 | O48: USD | P48: 100 KG
B49: XXXXX1 | C49: 45444 | D49: 45454 | E49: =_xlfn.XLOOKUP('Prices Database'!B49,'Customers Masterdata'!F:F,'Customers Masterdata'!G:G) -> Cust A | F49: V2 | G49: No Changes | H49: Discount | I49: 0.1 | J49: =B49&C49&D49&F49 -> XXXXX14544445454V2 | K49: Additives | L49: DO6 | M49: PRODUCT 6 | N49: 846 | O49: USD | P49: 100 KG
B50: XXXXX1 | C50: 45444 | D50: 45454 | E50: =_xlfn.XLOOKUP('Prices Database'!B50,'Customers Masterdata'!F:F,'Customers Masterdata'!G:G) -> Cust A | F50: V2 | G50: No Changes | H50: Discount | I50: 0.1 | J50: =B50&C50&D50&F50 -> XXXXX14544445454V2 | K50: Additives | L50: DO7 | M50: PRODUCT 7 | N50: 897.3 | O50: USD | P50: 100 KG
B51: XXXXX1 | C51: 45444 | D51: 45454 | E51: =_xlfn.XLOOKUP('Prices Database'!B51,'Customers Masterdata'!F:F,'Customers Masterdata'!G:G) -> Cust A | F51: V2 | G51: No Changes | H51: Discount | I51: 0.1 | J51: =B51&C51&D51&F51 -> XXXXX14544445454V2 | K51: Additives | L51: DO8 | M51: PRODUCT 8 | N51: 260.1 | O51: USD | P51: 100 KG
B52: XXXXX1 | C52: 45444 | D52: 45454 | E52: =_xlfn.XLOOKUP('Prices Database'!B52,'Customers Masterdata'!F:F,'Customers Masterdata'!G:G) -> Cust A | F52: V2 | G52: No Changes | H52: Discount | I52: 0.1 | J52: =B52&C52&D52&F52 -> XXXXX14544445454V2 | K52: Additives | L52: DO9 | M52: PRODUCT 9 | N52: 612.9 | O52: USD | P52: 100 KG
B53: XXXXX1 | C53: 45444 | D53: 45454 | E53: =_xlfn.XLOOKUP('Prices Database'!B53,'Customers Masterdata'!F:F,'Customers Masterdata'!G:G) -> Cust A | F53: V2 | G53: No Changes | H53: Discount | I53: 0.1 | J53: =B53&C53&D53&F53 -> XXXXX14544445454V2 | K53: Additives | L53: DO10 | M53: PRODUCT 10 | N53: 927.9 | O53: USD | P53: 100 KG
B54: XXXXX1 | C54: 45444 | D54: 45454 | E54: =_xlfn.XLOOKUP('Prices Database'!B54,'Customers Masterdata'!F:F,'Customers Masterdata'!G:G) -> Cust A | F54: V2 | G54: No Changes | H54: Discount | I54: 0.1 | J54: =B54&C54&D54&F54 -> XXXXX14544445454V2 | K54: Additives | L54: DO11 | M54: PRODUCT 11 | N54: 733.5 | O54: USD | P54: 100 KG
B55: XXXXX1 | C55: 45444 | D55: 45454 | E55: =_xlfn.XLOOKUP('Prices Database'!B55,'Customers Masterdata'!F:F,'Customers Masterdata'!G:G) -> Cust A | F55: V2 | G55: No Changes | H55: Discount | I55: 0.1 | J55: =B55&C55&D55&F55 -> XXXXX14544445454V2 | K55: Additives | L55: DO12 | M55: PRODUCT 12 | N55: 228.6 | O55: USD | P55: 100 KG
B56: XXXXX1 | C56: 45444 | D56: 45454 | E56: =_xlfn.XLOOKUP('Prices Database'!B56,'Customers Masterdata'!F:F,'Customers Masterdata'!G:G) -> Cust A | F56: V2 | G56: No Changes | H56: Discount | I56: 0.1 | J56: =B56&C56&D56&F56 -> XXXXX14544445454V2 | K56: Additives | L56: DO13 | M56: PRODUCT 13 | N56: 1214.1 | O56: USD | P56: 100 KG
B57: XXXXX1 | C57: 45444 | D57: 45454 | E57: =_xlfn.XLOOKUP('Prices Database'!B57,'Customers Masterdata'!F:F,'Customers Masterdata'!G:G) -> Cust A | F57: V2 | G57: No Changes | H57: Discount | I57: 0.1 | J57: =B57&C57&D57&F57 -> XXXXX14544445454V2 | K57: EAL | L57: QS1 | M57: PRODUCT 14 | N57: 1053.9 | O57: USD | P57: 100 L
... B85: XXXXX1 | C85: 45444 | D85: 45454 | E85: =_xlfn.XLOOKUP('Prices Database'!B85,'Customers Masterdata'!F:F,'Customers Masterdata'!G:G) -> Cust A | F85: V2 | G85: No Changes | H85: Discount | I85: 0 | J85: =B85&C85&D85&F85 -> XXXXX14544445454V2 | K85: Synthetic auxiliary | L85: QS29 | M85: PRODUCT 42 | N85: 1298 | O85: USD | P85: 100 L
B86: XXXXX1 | C86: 45444 | D86: 45454 | E86: =_xlfn.XLOOKUP('Prices Database'!B86,'Customers Masterdata'!F:F,'Customers Masterdata'!G:G) -> Cust A | F86: V2 | G86: New Product | H86: Net Price | I86: Net Price | J86: =B86&C86&D86&F86 -> XXXXX14544445454V2 | K86: Synthetic auxiliary | L86: QS30 | M86: PRODUCT 43 | N86: 500 | O86: USD | P86: 100 L
B87: XXXXX1 | C87: 45444 | D87: 45454 | E87: =_xlfn.XLOOKUP('Prices Database'!B87,'Customers Masterdata'!F:F,'Customers Masterdata'!G:G) -> Cust A | F87: V2 | G87: New Product | H87: Net Price | I87: Net Price | J87: =B87&C87&D87&F87 -> XXXXX14544445454V2 | K87: Synthetic auxiliary | L87: QS31 | M87: PRODUCT 44 | N87: 500 | O87: USD | P87: 100 L
B88: XXXXX1 | C88: 45444 | D88: 45454 | E88: =_xlfn.XLOOKUP('Prices Database'!B88,'Customers Masterdata'!F:F,'Customers Masterdata'!G:G) -> Cust A | F88: V2 | G88: New Product | H88: Net Price | I88: Net Price | J88: =B88&C88&D88&F88 -> XXXXX14544445454V2 | K88: Synthetic auxiliary | L88: QS32 | M88: PRODUCT 45 | N88: 500 | O88: USD | P88: 100 L
B89: XXXXX2 | C89: 45658 | D89: 45658 | E89: =_xlfn.XLOOKUP('Prices Database'!B89,'Customers Masterdata'!F:F,'Customers Masterdata'!G:G) -> Cust B | F89: V1 | G89: New Product | H89: Discount | I89: Net Price | J89: =B89&C89&D89&F89 -> XXXXX24565845658V1 | K89: Additives | L89: DO3 | M89: PRODUCT 3 | N89: 46.1 | O89: EUR | P89: 100 KG
B90: XXXXX2 | C90: 45658 | D90: 45658 | E90: =_xlfn.XLOOKUP('Prices Database'!B90,'Customers Masterdata'!F:F,'Customers Masterdata'!G:G) -> Cust B | F90: V1 | G90: New Product | H90: Discount | I90: Net Price | J90: =B90&C90&D90&F90 -> XXXXX24565845658V1 | K90: Additives | L90: DO4 | M90: PRODUCT 4 | N90: 34.1 | O90: EUR | P90: 100 KG
B91: XXXXX2 | C91: 45658 | D91: 45658 | E91: =_xlfn.XLOOKUP('Prices Database'!B91,'Customers Masterdata'!F:F,'Customers Masterdata'!G:G) -> Cust B | F91: V1 | G91: New Product | H91: Discount | I91: Net Price | J91: =B91&C91&D91&F91 -> XXXXX24565845658V1 | K91: Additives | L91: DO5 | M91: PRODUCT 5 | N91: 168.1 | O91: EUR | P91: 100 KG
B92: XXXXX2 | C92: 45658 | D92: 45658 | E92: =_xlfn.XLOOKUP('Prices Database'!B92,'Customers Masterdata'!F:F,'Customers Masterdata'!G:G) -> Cust B | F92: V1 | G92: New Product | H92: Discount | I92: Net Price | J92: =B92&C92&D92&F92 -> XXXXX24565845658V1 | K92: Additives | L92: DO6 | M92: PRODUCT 6 | N92: 94 | O92: EUR | P92: 100 KG
B93: XXXXX2 | C93: 45658 | D93: 45658 | E93: =_xlfn.XLOOKUP('Prices Database'!B93,'Customers Masterdata'!F:F,'Customers Masterdata'!G:G) -> Cust B | F93: V1 | G93: New Product | H93: Discount | I93: Net Price | J93: =B93&C93&D93&F93 -> XXXXX24565845658V1 | K93: Additives | L93: DO7 | M93: PRODUCT 7 | N93: 99.7 | O93: EUR | P93: 100 KG
B94: XXXXX2 | C94: 45658 | D94: 45658 | E94: =_xlfn.XLOOKUP('Prices Database'!B94,'Customers Masterdata'!F:F,'Customers Masterdata'!G:G) -> Cust B | F94: V1 | G94: New Product | H94: Discount | I94: Net Price | J94: =B94&C94&D94&F94 -> XXXXX24565845658V1 | K94: Additives | L94: DO8 | M94: PRODUCT 8 | N94: 28.9 | O94: EUR | P94: 100 KG
...

Sheet Packaging Masterdata
A1: Packagin Version | B1: Product Type | C1: Packaging Name | D1: Price | E1: Currency | F1: Unit
A2: USD-Standard | C2: Packaging charge
A3: USD-Standard | B3: Packaging charge | C3: Packaging charge for IBC | D3: 36 | E3: USD | F3: 100 KG/L
A4: USD-Standard | B4: Packaging charge | C4: Packaging charge for Drum | D4: 48 | E4: USD | F4: 100 KG/L
A5: USD-Standard | B5: Packaging charge | C5: Packaging charge for Pail | D5: 10 | E5: USD | F5: 100 KG
A6: USD-Standard | B6: Packaging charge | C6: Packaging charge for Pail | D6: 50 | E6: USD | F6: 100 L
A7: USD-Standard
A8: USD-Standard | C8: Pallets
A9: USD-Standard | B9: Pallets | C9: Standard pallet 120 x 120 (for delivery by truck) | D9: 50 | E9: USD | F9: pallet
A10: USD-Standard | B10: Pallets | C10: Maritime Pallet 114 x 114 (for delivery by container) | D10: 45 | E10: USD | F10: pallet
A15: Packagin Version | B15: Product Type | C15: Packaging Name | D15: Price | E15: Currency | F15: Unit
C16: Packaging charge
A17: EUR-Standard | B17: Packaging charge | C17: Packaging charge for IBC | D17: 28 | E17: EUR | F17: 100 KG/L
A18: EUR-Standard | B18: Packaging charge | C18: Packaging charge for Drum | D18: 35 | E18: EUR | F18: 100 KG/L
A19: EUR-Standard | B19: Packaging charge | C19: Packaging charge for Pail | D19: 56 | E19: EUR | F19: 100 KG
A20: EUR-Standard | B20: Packaging charge | C20: Packaging charge for Pail | D20: 45 | E20: EUR | F20: 100 L
C22: Pallets
A23: EUR-Standard | B23: Pallets | C23: Standard pallet 120 x 120 (for delivery by truck) | D23: 44 | E23: EUR | F23: pallet
A24: EUR-Standard | B24: Pallets | C24: Maritime Pallet 114 x 114 (for delivery by container) | D24: 68 | E24: EUR | F24: pallet

Sheet Customers Masterdata
A1: Zone | B1: Country | C1: Customer Type | D1: Comment on Business Model | E1: Customer ref. type SAP | F1: Customer ref. SAP | G1: Customer Short Name | H1: Customer Full Name | I1: Currency | J1: Packagin Version | K1: Pice List Managed by | L1: Customer SPOC | M1: Effective | N1: Mailing date | O1: Last Price List Version | P1: Last Price List ID | Q1: Mailing TO: Customer | R1: Internal COPY: SPOC + RZM + Other | S1: Internal COPY to: PBP (Costing manager) | T1: COPY to: PBP common mail box
A2: A-Zone | B2: Country A | C2: Partner | D2: Blending and Distribution in Country A | E2: Bill to Code | F2: XXXXX1 | G2: Cust A | H2: Customer A | I2: USD | J2: USD-Standard | K2: PBP | L2: SEMEIA Business Dev | M2: 45444 | N2: 45454 | O2: V2 | P2: =T_CustomerMasterdata[[#This Row],[Customer ref. SAP]]&T_CustomerMasterdata[[#This Row],[Effective]]&T_CustomerMasterdata[[#This Row],[Mailing date]]&T_CustomerMasterdata[[#This Row],[Last Price List Version]] -> XXXXX14544445454V2 | Q2: customerApersonBX@email.com; customerAPersonBX@email.com; | R2: internalpersonA@internal.com; internalpersonB@internal.com; | S2: =V_Email_PBPCostingManager -> internalpersonPBP@internal.com | T2: =V_Email_PBPCommon -> examplePBPCommon.email@example.com
A3: B-Zone | B3: Country B | C3: Affiliate | D3: Distribution in Country B | E3: Bill to Code | F3: XXXXX2 | G3: Cust B | H3: Customer B | I3: EUR | J3: EUR-Standard | K3: PBP | L3: APAC Business Dev | M3: 45658 | N3: 45658 | O3: V1 | P3: =T_CustomerMasterdata[[#This Row],[Customer ref. SAP]]&T_CustomerMasterdata[[#This Row],[Effective]]&T_CustomerMasterdata[[#This Row],[Mailing date]]&T_CustomerMasterdata[[#This Row],[Last Price List Version]] -> XXXXX24565845658V1 | Q3: customerBpersonA@email.com; | R3: internalpersonC@internal.com; | S3: =V_Email_PBPCostingManager -> internalpersonPBP@internal.com | T3: =V_Email_PBPCommon -> examplePBPCommon.email@example.com
A4: B-Zone | B4: Country B | C4: Affiliate | D4: Distribution in Country B | E4: Bill to Code | F4: XXXXX3 | G4: Cust GBP | H4: Customer GBP | I4: GBP | J4: GBP-Standard | K4: PBP | L4: APAC Business Dev | M4: 45658 | N4: 45658 | O4: V1 | P4: =T_CustomerMasterdata[[#This Row],[Customer ref. SAP]]&T_CustomerMasterdata[[#This Row],[Effective]]&T_CustomerMasterdata[[#This Row],[Mailing date]]&T_CustomerMasterdata[[#This Row],[Last Price List Version]] -> XXXXX34565845658V1 | Q4: customerBpersonA@email.com; | R4: internalpersonC@internal.com; | S4: =V_Email_PBPCostingManager -> internalpersonPBP@internal.com | T4: =V_Email_PBPCommon -> examplePBPCommon.email@example.com

Sheet Standard EPL
A1: Product type | B1: RIP code | C1: Product | D1: Net price (Currency / Unit) | E1: Currency | F1: Unit | I1: Product type | J1: RIP code | K1: Product | L1: Net price (Currency / Unit) | M1: Currency | N1: Unit
A2: Additives | B2: DO1 | C2: PRODUCT 1 | D2: 1446 | E2: USD | F2: 100 KG | I2: Additives | J2: DO3 | K2: PRODUCT 3 | L2: 46.1 | M2: EUR | N2: 100 KG
A3: Additives | B3: DO2 | C3: PRODUCT 2 | D3: 81 | E3: USD | F3: 100 KG | I3: Additives | J3: DO4 | K3: PRODUCT 4 | L3: 34.1 | M3: EUR | N3: 100 KG
A4: Additives | B4: DO3 | C4: PRODUCT 3 | D4: 461 | E4: USD | F4: 100 KG | I4: Additives | J4: DO5 | K4: PRODUCT 5 | L4: 168.1 | M4: EUR | N4: 100 KG
A5: Additives | B5: DO4 | C5: PRODUCT 4 | D5: 341 | E5: USD | F5: 100 KG | I5: Additives | J5: DO6 | K5: PRODUCT 6 | L5: 94 | M5: EUR | N5: 100 KG
A6: Additives | B6: DO5 | C6: PRODUCT 5 | D6: 1681 | E6: USD | F6: 100 KG | I6: Additives | J6: DO7 | K6: PRODUCT 7 | L6: 99.7 | M6: EUR | N6: 100 KG
A7: Additives | B7: DO6 | C7: PRODUCT 6 | D7: 940 | E7: USD | F7: 100 KG | I7: Additives | J7: DO8 | K7: PRODUCT 8 | L7: 28.9 | M7: EUR | N7: 100 KG
A8: Additives | B8: DO7 | C8: PRODUCT 7 | D8: 997 | E8: USD | F8: 100 KG | I8: Additives | J8: DO9 | K8: PRODUCT 9 | L8: 68.1 | M8: EUR | N8: 100 KG
A9: Additives | B9: DO8 | C9: PRODUCT 8 | D9: 289 | E9: USD | F9: 100 KG | I9: Additives | J9: DO10 | K9: PRODUCT 10 | L9: 103.1 | M9: EUR | N9: 100 KG
A10: Additives | B10: DO9 | C10: PRODUCT 9 | D10: 681 | E10: USD | F10: 100 KG | I10: Additives | J10: DO11 | K10: PRODUCT 11 | L10: 81.5 | M10: EUR | N10: 100 KG
A11: Additives | B11: DO10 | C11: PRODUCT 10 | D11: 1031 | E11: USD | F11: 100 KG | I11: Additives | J11: DO12 | K11: PRODUCT 12 | L11: 25.4 | M11: EUR | N11: 100 KG
A12: Additives | B12: DO11 | C12: PRODUCT 11 | D12: 815 | E12: USD | F12: 100 KG | I12: Additives | J12: DO13 | K12: PRODUCT 13 | L12: 134.9 | M12: EUR | N12: 100 KG
A13: Additives | B13: DO12 | C13: PRODUCT 12 | D13: 254 | E13: USD | F13: 100 KG
A14: Additives | B14: DO13 | C14: PRODUCT 13 | D14: 1349 | E14: USD | F14: 100 KG
A15: EAL | B15: QS1 | C15: PRODUCT 14 | D15: 1171 | E15: USD | F15: 100 L
A16: EAL | B16: QS2 | C16: PRODUCT 15 | D16: 227 | E16: USD | F16: 100 L
A17: EAL | B17: QS3 | C17: PRODUCT 16 | D17: 461 | E17: USD | F17: 100 L
A18: EAL | B18: QS4 | C18: PRODUCT 17 | D18: 1005 | E18: USD | F18: 100 L
A19: Main grades | B19: QS5 | C19: PRODUCT 18 | D19: 457 | E19: USD | F19: 100 L
A20: Main grades | B20: QS6 | C20: PRODUCT 19 | D20: 666 | E20: USD | F20: 100 L
A21: Main grades | B21: QS7 | C21: PRODUCT 20 | D21: 1438 | E21: USD | F21: 100 L
A22: Main grades | B22: QS8 | C22: PRODUCT 21 | D22: 419 | E22: USD | F22: 100 L
A23: Main grades | B23: QS9 | C23: PRODUCT 22 | D23: 703 | E23: USD | F23: 100 L
A24: Mineral auxiliary | B24: QS10 | C24: PRODUCT 23 | D24: 1585 | E24: USD | F24: 100 L
... A46: Synthetic auxiliary | B46: QS32 | C46: PRODUCT 45 | D46: 362 | E46: USD | F46: 100 L

Sheet Products Masterdata
A1: Plant | B1: Product type | C1: RIP code | D1: Product
B2: Additives | C2: DO1 | D2: PRODUCT 1
B3: Additives | C3: DO2 | D3: PRODUCT 2
B4: Additives | C4: DO3 | D4: PRODUCT 3
B5: Additives | C5: DO4 | D5: PRODUCT 4
B6: Additives | C6: DO5 | D6: PRODUCT 5
B7: Additives | C7: DO6 | D7: PRODUCT 6
B8: Additives | C8: DO7 | D8: PRODUCT 7
B9: Additives | C9: DO8 | D9: PRODUCT 8
B10: Additives | C10: DO9 | D10: PRODUCT 9
B11: Additives | C11: DO10 | D11: PRODUCT 10
B12: Additives | C12: DO11 | D12: PRODUCT 11
B13: Additives | C13: DO12 | D13: PRODUCT 12
... B46: Synthetic auxiliary | C46: QS32 | D46: PRODUCT 45
